<?xml version="1.0"?>
<robot name="IRB7600">

  <material name="blue">
    <color rgba="0 0 0.8 1"/>
  </material>
  <material name="black">
    <color rgba="0 0 0 1"/>
  </material>
  <material name="white">
    <color rgba="1 1 1 1"/>
  </material>
  

 <link name="base_link">
    <visual>
      <origin rpy="0 0 0" xyz = "0 0 -0.1"/>
      <geometry>
        <cylinder length="0.2" radius="1.2"/>
      </geometry>
      <material name="blue"/>
    </visual>
  </link>
  
  
  <joint name="base_link_link1" type="continuous">
    <parent link="base_link"/>
    <child link="link1"/>
    <axis xyz="0 0 1"/>
    <origin rpy="0 0 0" xyz = "0 0 0.78"/>
  </joint>
  
   <link name="link1">
    <visual>
      <origin rpy="0 0 0" xyz = "0 0 -0.39"/>
      <geometry>
        <cylinder length="0.8" radius="0.2"/>
      </geometry>
      <material name="black"/>
    </visual>
  </link>
  
  <joint name="link1_link2" type="continuous">
    <parent link="link1"/>
    <child link="link2"/>
       <axis xyz="0 0 1"/>
       <origin rpy="1.571 -1.571 0" xyz = "0.41 0 0"/>
  </joint>
  
  <link name="link2">
    <visual>
      <geometry>
        <cylinder length="0.6" radius="0.2"/>
      </geometry>
      <material name="black"/>
    </visual>
  </link>
  
  <joint name="link2_link3" type="continuous">
    <parent link="link2"/>
    <child link="link3"/>
    <axis xyz="0 0 1"/>
    <origin rpy="0 0 0" xyz = "1.075 0 0"/>
  </joint>
  
  <link name="link3">
    <visual>
      <geometry>
        <cylinder length="0.6" radius="0.2"/>
      </geometry>
      <material name="black"/>
    </visual>
  </link>
  
   <joint name="link3_link4" type="continuous">
    <parent link="link3"/>
    <child link="link4"/>
       <axis xyz="0 0 1"/>
       <origin rpy="1.571 0 0" xyz = "0.165 -1.056 0"/>
  </joint>
  
  <link name="link4">
    <visual>
     <origin rpy="0 0 0" xyz = "0 0 -0.5"/>
      <geometry>
        <cylinder length="0.6" radius="0.1"/>
      </geometry>
      <material name="black"/>
    </visual>
  </link>
   
  <joint name="link4_link5" type="continuous">
    <parent link="link4"/>
    <child link="link5"/>
       <axis xyz="0 0 1"/>
       <origin rpy="-1.571 0 0" xyz = "0 0 0"/>
  </joint>
  
  <link name="link5">
    <visual>
      <geometry>
        <cylinder length="0.3" radius="0.1"/>
      </geometry>
      <material name="black"/>
    </visual>
  </link>
  
  <joint name="link5_link6" type="continuous">
    <parent link="link5"/>
    <child link="link6"/>
       <axis xyz="0 0 1"/>
       <origin rpy="1.571 0 0" xyz = "0 0 0"/>
  </joint>
  
  <link name="link6">
    <visual>
	<origin rpy="0 0 0" xyz = "0 0 0.125"/>
      <geometry>
        <cylinder length="0.25" radius="0.1"/>
      </geometry>
      <material name="black"/>
    </visual>
  </link>
  
  <joint name="link6_tool" type="fixed">
    <parent link="link6"/>
    <child link="tool"/>

       <origin rpy="0 0 0" xyz = "0 0 0.25"/>
  </joint>
  
  <link name="tool">
    <visual>
	<origin rpy="0 0 0" xyz = "0 0 0"/>
      <geometry>
        <cylinder length="0.01" radius="0.2"/>
      </geometry>
      <material name="white"/>
    </visual>
  </link>
  
</robot> 
